Workbook

Sheet Sheet1
B7: Row Labels | C7: Count of Invoice Number | D7: Sum of Invoice Amount
B8: PG1 | C8: 36 | D8: 1731476
B9: PG2 | C9: 43 | D9: 1648769
B10: PG3 | C10: 38 | D10: 1428238
B11: PG4 | C11: 36 | D11: 1618733
B12: PG5 | C12: 27 | D12: 1347736
B13: PG6 | C13: 54 | D13: 2731536
B14: PG7 | C14: 41 | D14: 2167189
B15: PG8 | C15: 40 | D15: 1612789
B16: PG9 | C16: 34 | D16: 1595725
B17: PG10 | C17: 37 | D17: 1719915
B18: Grand Total | C18: 386 | D18: 17602106

Sheet Date picker
B5: Column1 | C5: Column2
B6: FY
B7: Period
B8: Date | C8: 46234
B9: Time
C18: https://docs.google.com/spreadsheets/d/1GCdJNkdXAHeJCQ21Qb221Jc3h_niCMOGPAa-cX-2LiM/export?format=xlsx

Sheet Fake Data Source
E2: 0 | G2: /1 | K2: 46204 | L2: 46326
A3: Pay Group | B3: Validation Status | C3: Invoice Creation Date | D3: Supplier or Party Name | E3: Site | F3: Identifying PO | G3: Invoice Number | H3: Payment Terms Name | I3: Invoice Amount | J3: Requester | K3: Invoice Description | L3: Invoice Date | M3: PQ Due Date | N3: PQ Days Left | O3: PQ Status
A4: PG1 | B4: Incomplete | C4: =L4-1 -> 46303 | D4: Supplier 1 | E4: SUP001 | F4: =CONCATENATE($E$2,RANDBETWEEN(2000000,2999999),$G$2) -> 02704603/1 | H4: {=INDEX('Fake Data Source'!$S$4:$S$57,RANDBETWEEN(1,ROWS('Fake Data Source'!$S$4:$S$57)))} -> D-55-0 | I4: =RANDBETWEEN(1000,900000) -> 549281 | J4: Doe, John | L4: =RANDBETWEEN($K$2,$L$2) -> 46304 | S4: Immediate
A5: PG2 | B5: Not Validated | D5: Supplier 2 | E5: SUP002 | H5: {=INDEX('Fake Data Source'!$S$4:$S$57,RANDBETWEEN(1,ROWS('Fake Data Source'!$S$4:$S$57)))} -> D-21-0 | J5: Doe, Jane | L5: =RANDBETWEEN($K$2,$L$2) -> 46209 | S5: D-7-0
A6: PG3 | B6: Needs Revalidation | D6: Supplier 3 | E6: SUP003 | H6: {=INDEX('Fake Data Source'!$S$4:$S$57,RANDBETWEEN(1,ROWS('Fake Data Source'!$S$4:$S$57)))} -> D-20-0 | L6: =RANDBETWEEN($K$2,$L$2) -> 46308 | S6: D-7-0.25
A7: PG4 | B7: Validated | D7: Supplier 4 | E7: SUP004 | H7: {=INDEX('Fake Data Source'!$S$4:$S$57,RANDBETWEEN(1,ROWS('Fake Data Source'!$S$4:$S$57)))} -> D-60-0 | L7: =RANDBETWEEN($K$2,$L$2) -> 46316 | S7: D-7-1.5
A8: PG5 | B8: Cancelled | D8: Supplier 5 | E8: SUP005 | H8: {=INDEX('Fake Data Source'!$S$4:$S$57,RANDBETWEEN(1,ROWS('Fake Data Source'!$S$4:$S$57)))} -> D-15-0 | L8: =RANDBETWEEN($K$2,$L$2) -> 46259 | S8: D-7-2
A9: PG6 | D9: Supplier 6 | E9: SUP006 | H9: {=INDEX('Fake Data Source'!$S$4:$S$57,RANDBETWEEN(1,ROWS('Fake Data Source'!$S$4:$S$57)))} -> D-31-0 | L9: =RANDBETWEEN($K$2,$L$2) -> 46244 | S9: D-7-2.5
A10: PG7 | D10: Supplier 7 | E10: SUP007 | H10: {=INDEX('Fake Data Source'!$S$4:$S$57,RANDBETWEEN(1,ROWS('Fake Data Source'!$S$4:$S$57)))} -> D-12-2 | L10: =RANDBETWEEN($K$2,$L$2) -> 46312 | S10: D-7-5
A11: PG8 | D11: Supplier 8 | E11: SUP008 | H11: {=INDEX('Fake Data Source'!$S$4:$S$57,RANDBETWEEN(1,ROWS('Fake Data Source'!$S$4:$S$57)))} -> D-14-0.5 | L11: =RANDBETWEEN($K$2,$L$2) -> 46320 | S11: D-10-0
A12: PG9 | D12: Supplier 9 | E12: SUP009 | H12: {=INDEX('Fake Data Source'!$S$4:$S$57,RANDBETWEEN(1,ROWS('Fake Data Source'!$S$4:$S$57)))} -> D-28-0 | L12: =RANDBETWEEN($K$2,$L$2) -> 46212 | S12: D-10-2
A13: PG10 | D13: Supplier 10 | E13: SUP010 | H13: {=INDEX('Fake Data Source'!$S$4:$S$57,RANDBETWEEN(1,ROWS('Fake Data Source'!$S$4:$S$57)))} -> D-14-2 | L13: =RANDBETWEEN($K$2,$L$2) -> 46285 | S13: D-12-2
D14: Supplier 11 | E14: SUP011 | H14: {=INDEX('Fake Data Source'!$S$4:$S$57,RANDBETWEEN(1,ROWS('Fake Data Source'!$S$4:$S$57)))} -> D-7-2 | L14: =RANDBETWEEN($K$2,$L$2) -> 46212 | S14: D-14-0
D15: Supplier 12 | E15: SUP012 | H15: {=INDEX('Fake Data Source'!$S$4:$S$57,RANDBETWEEN(1,ROWS('Fake Data Source'!$S$4:$S$57)))} -> M-28-1 | L15: =RANDBETWEEN($K$2,$L$2) -> 46249 | S15: D-14-0.5
D16: Supplier 13 | E16: SUP013 | H16: {=INDEX('Fake Data Source'!$S$4:$S$57,RANDBETWEEN(1,ROWS('Fake Data Source'!$S$4:$S$57)))} -> D-20-0 | L16: =RANDBETWEEN($K$2,$L$2) -> 46275 | S16: D-14-1
D17: Supplier 14 | E17: SUP014 | H17: {=INDEX('Fake Data Source'!$S$4:$S$57,RANDBETWEEN(1,ROWS('Fake Data Source'!$S$4:$S$57)))} -> D-31-0 | L17: =RANDBETWEEN($K$2,$L$2) -> 46268 | S17: D-14-1.25
D18: Supplier 15 | E18: SUP015 | H18: {=INDEX('Fake Data Source'!$S$4:$S$57,RANDBETWEEN(1,ROWS('Fake Data Source'!$S$4:$S$57)))} -> M-30-0 | S18: D-14-1.5
D19: Supplier 16 | E19: SUP016 | H19: {=INDEX('Fake Data Source'!$S$4:$S$57,RANDBETWEEN(1,ROWS('Fake Data Source'!$S$4:$S$57)))} -> D-14-2 | S19: D-14-2
D20: Supplier 17 | E20: SUP017 | H20: {=INDEX('Fake Data Source'!$S$4:$S$57,RANDBETWEEN(1,ROWS('Fake Data Source'!$S$4:$S$57)))} -> Immediate | S20: D-14-2.5
D21: Supplier 18 | E21: SUP018 | H21: {=INDEX('Fake Data Source'!$S$4:$S$57,RANDBETWEEN(1,ROWS('Fake Data Source'!$S$4:$S$57)))} -> D-14-1 | S21: D-15-0
D22: Supplier 19 | E22: SUP019 | H22: {=INDEX('Fake Data Source'!$S$4:$S$57,RANDBETWEEN(1,ROWS('Fake Data Source'!$S$4:$S$57)))} -> D-7-0.25 | S22: D-15-1.7
D23: Supplier 20 | E23: SUP020 | H23: {=INDEX('Fake Data Source'!$S$4:$S$57,RANDBETWEEN(1,ROWS('Fake Data Source'!$S$4:$S$57)))} -> D-90-0 | S23: D-20-0
D24: Supplier 21 | E24: SUP021 | H24: {=INDEX('Fake Data Source'!$S$4:$S$57,RANDBETWEEN(1,ROWS('Fake Data Source'!$S$4:$S$57)))} -> D-21-0 | S24: D-21-0
D25: Supplier 22 | E25: SUP022 | H25: {=INDEX('Fake Data Source'!$S$4:$S$57,RANDBETWEEN(1,ROWS('Fake Data Source'!$S$4:$S$57)))} -> D-30-0 | S25: D-24-0
D26: Supplier 23 | E26: SUP023 | H26: {=INDEX('Fake Data Source'!$S$4:$S$57,RANDBETWEEN(1,ROWS('Fake Data Source'!$S$4:$S$57)))} -> D-14-0 | S26: D-25-0
D27: Supplier 24 | E27: SUP024 | H27: {=INDEX('Fake Data Source'!$S$4:$S$57,RANDBETWEEN(1,ROWS('Fake Data Source'!$S$4:$S$57)))} -> D-30-4.5 | S27: D-28-0
D28: Supplier 25 | E28: SUP025 | H28: {=INDEX('Fake Data Source'!$S$4:$S$57,RANDBETWEEN(1,ROWS('Fake Data Source'!$S$4:$S$57)))} -> D-14-2.5 | S28: D-28-1
D29: Supplier 26 | E29: SUP026 | H29: {=INDEX('Fake Data Source'!$S$4:$S$57,RANDBETWEEN(1,ROWS('Fake Data Source'!$S$4:$S$57)))} -> M2-10-0 | S29: D-30-0
... D57: Supplier 54 | E57: SUP054 | H57: {=INDEX('Fake Data Source'!$S$4:$S$57,RANDBETWEEN(1,ROWS('Fake Data Source'!$S$4:$S$57)))} -> M-10-0 | S57: M2-30-0
D58: Supplier 55 | E58: SUP055 | H58: {=INDEX('Fake Data Source'!$S$4:$S$57,RANDBETWEEN(1,ROWS('Fake Data Source'!$S$4:$S$57)))} -> D-60-0
D59: Supplier 56 | E59: SUP056 | H59: {=INDEX('Fake Data Source'!$S$4:$S$57,RANDBETWEEN(1,ROWS('Fake Data Source'!$S$4:$S$57)))} -> D-14-1.5
D60: Supplier 57 | E60: SUP057 | H60: {=INDEX('Fake Data Source'!$S$4:$S$57,RANDBETWEEN(1,ROWS('Fake Data Source'!$S$4:$S$57)))} -> D-31-0
D61: Supplier 58 | E61: SUP058 | H61: {=INDEX('Fake Data Source'!$S$4:$S$57,RANDBETWEEN(1,ROWS('Fake Data Source'!$S$4:$S$57)))} -> M-28-1
D62: Supplier 59 | E62: SUP059 | H62: {=INDEX('Fake Data Source'!$S$4:$S$57,RANDBETWEEN(1,ROWS('Fake Data Source'!$S$4:$S$57)))} -> D-7-2
D63: Supplier 60 | E63: SUP060 | H63: {=INDEX('Fake Data Source'!$S$4:$S$57,RANDBETWEEN(1,ROWS('Fake Data Source'!$S$4:$S$57)))} -> D-30-1.5
D64: Supplier 61 | E64: SUP061 | H64: {=INDEX('Fake Data Source'!$S$4:$S$57,RANDBETWEEN(1,ROWS('Fake Data Source'!$S$4:$S$57)))} -> D-30-1.5
D65: Supplier 62 | E65: SUP062 | H65: {=INDEX('Fake Data Source'!$S$4:$S$57,RANDBETWEEN(1,ROWS('Fake Data Source'!$S$4:$S$57)))} -> M-28-1
D66: Supplier 63 | E66: SUP063 | H66: {=INDEX('Fake Data Source'!$S$4:$S$57,RANDBETWEEN(1,ROWS('Fake Data Source'!$S$4:$S$57)))} -> D-14-0.5
D67: Supplier 64 | E67: SUP064 | H67: {=INDEX('Fake Data Source'!$S$4:$S$57,RANDBETWEEN(1,ROWS('Fake Data Source'!$S$4:$S$57)))} -> M-16-0
D68: Supplier 65 | E68: SUP065 | H68: {=INDEX('Fake Data Source'!$S$4:$S$57,RANDBETWEEN(1,ROWS('Fake Data Source'!$S$4:$S$57)))} -> Immediate
...

Sheet FAKE REPORT
A2: Pay Group | B2: Validation Status | C2: Invoice Creation Date | D2: Supplier or Party Name | E2: Site | F2: Identifying PO | G2: Invoice Number | H2: Payment Terms Name | I2: Invoice Amount | J2: Requester | K2: Invoice Description | L2: Invoice Date
A3: PG3 | B3: Incomplete | C3: 46292 | D3: Supplier 303 | E3: SUP303 | F3: 02660484/1 | G3: INV530878 | H3: D-45-0 | I3: 67890 | L3: 46293
A4: PG4 | B4: Needs Revalidation | C4: 46228 | D4: Supplier 428 | E4: SUP428 | F4: 02221636/1 | G4: INV125318288 | H4: D-10-0 | I4: 75077 | L4: 46318
A5: PG6 | B5: Needs Revalidation | C5: 46242 | D5: Supplier 62 | E5: SUP062 | F5: 02926544/1 | G5: INV576563779 | H5: D-14-1.25 | I5: 80070 | L5: 46308
A6: PG10 | B6: Needs Revalidation | C6: 46241 | D6: Supplier 194 | E6: SUP194 | F6: 02582130/1 | G6: INV105432217 | H6: D-50-0 | I6: 34929 | L6: 46276
A7: PG6 | B7: Validated | C7: 46285 | D7: Supplier 378 | E7: SUP378 | F7: 02762159/1 | G7: INV528678403 | H7: D-14-2 | I7: 46545 | L7: 46275
A8: PG1 | B8: Cancelled | C8: 46318 | D8: Supplier 488 | E8: SUP488 | F8: 02155101/1 | G8: INV149695241 | H8: D-20-0 | I8: 52679 | L8: 46208
A9: PG7 | B9: Not Validated | C9: 46321 | D9: Supplier 282 | E9: SUP282 | F9: 02036885/1 | G9: INV76277213 | H9: D-7-5 | I9: 46916 | L9: 46321
A10: PG6 | B10: Not Validated | C10: 46303 | D10: Supplier 143 | E10: SUP143 | F10: 02781054/1 | G10: INV882812081 | H10: M-25-0 | I10: 31642 | L10: 46311
A11: PG3 | B11: Incomplete | C11: 46293 | D11: Supplier 353 | E11: SUP353 | F11: 02273895/1 | G11: INV592097569 | H11: D-28-1 | I11: 61084 | L11: 46226
A12: PG6 | B12: Validated | C12: 46323 | D12: Supplier 146 | E12: SUP146 | F12: 02529850/1 | G12: INV730273642 | H12: D-60-2 | I12: 35963 | L12: 46272
A13: PG10 | B13: Not Validated | C13: 46289 | D13: Supplier 11 | E13: SUP011 | F13: 02666539/1 | G13: INV206800501 | H13: M-21-0.7 | I13: 1637 | L13: 46291
A14: PG10 | B14: Validated | C14: 46231 | D14: Supplier 312 | E14: SUP312 | F14: 02262683/1 | G14: INV498502573 | H14: D-7-1.5 | I14: 51564 | L14: 46270
... A10001: PG3 | B10001: Cancelled | C10001: 46308 | D10001: Supplier 163 | E10001: SUP163 | F10001: 02998147/1 | G10001: INV354764459 | H10001: D-90-0 | I10001: 37216 | L10001: 46266

Sheet Dates
F1: Date Lookup | U1: Folder Name Lookup
A2: Drop-down Dates | F2: P01 | G2: P02 | H2: P03 | I2: P04 | J2: P05 | K2: P06 | L2: P07 | M2: P08 | N2: P09 | O2: P10 | P2: P11 | Q2: P12 | U2: P01 | V2: P02 | W2: P03 | X2: P04 | Y2: P05 | Z2: P06 | AA2: P07 | AB2: P08 | AC2: P09 | AD2: P10 | AE2: P11 | AF2: P12 | AJ2: Period | AK2: Days | AL2: Bank Holidays | AM2: Files
A3: {=_xlfn._xlws.FILTER( INDEX($F$3:$Q$108, _xlfn.SEQUENCE(ROWS($F$3:$F$108)), MATCH('[1]Folder Location'!$F$11, $F$2:$Q$2, 0)), ($D$3:$D$108 = '[1]Folder Location'!$F$10) * ( INDEX($F$3:$Q$108, _xlfn.SEQUENCE(ROWS($F$3:$F$108)), MATCH('[1]Folder Location'!$F$11, $F$2:$Q$2, 0)) <> 0))} -> 46293 | C3: FY27 | D3: FY27 | E3: =TEXT( F3, "ddd") -> Mon | F3: 46111 | G3: =F27+3 -> 46146 | H3: =G22+3 -> 46174 | I3: =H22+3 -> 46202 | J3: =I27+3 -> 46237 | K3: =J22+3 -> 46265 | L3: =K22+3 -> 46293 | M3: =L27+3 -> 46328 | N3: =M22+3 -> 46356 | O3: =N22+3 -> 46384 | P3: =O27+3 -> 46419 | Q3: =P22+3 -> 46447 | U3: =YEAR(F3)&"_"&TEXT(MONTH(F3),"00")&"_"&TEXT(DAY(F3),"00") -> 2026_03_30 | V3: =YEAR(G3)&"_"&TEXT(MONTH(G3),"00")&"_"&TEXT(DAY(G3),"00") -> 2026_05_04 | W3: =YEAR(H3)&"_"&TEXT(MONTH(H3),"00")&"_"&TEXT(DAY(H3),"00") -> 2026_06_01 | X3: =YEAR(I3)&"_"&TEXT(MONTH(I3),"00")&"_"&TEXT(DAY(I3),"00") -> 2026_06_29 | Y3: =YEAR(J3)&"_"&TEXT(MONTH(J3),"00")&"_"&TEXT(DAY(J3),"00") -> 2026_08_03 | Z3: =YEAR(K3)&"_"&TEXT(MONTH(K3),"00")&"_"&TEXT(DAY(K3),"00") -> 2026_08_31 | AA3: =YEAR(L3)&"_"&TEXT(MONTH(L3),"00")&"_"&TEXT(DAY(L3),"00") -> 2026_09_28 | AB3: =YEAR(M3)&"_"&TEXT(MONTH(M3),"00")&"_"&TEXT(DAY(M3),"00") -> 2026_11_02 | ... AF3: =YEAR(Q3)&"_"&TEXT(MONTH(Q3),"00")&"_"&TEXT(DAY(Q3),"00") -> 2027_03_01 | AJ3: FY27 | AK3: {=_xlfn.DROP( IF(_xlfn._TRO_TRAILING( AL:AL) = "", "", TEXT(_xlfn._TRO_TRAILING( AL:AL), "ddd" )), ROW(AK3)-1)} -> Fri | AL3: 46115 | AM3: =YEAR(AL3)&"_"&TEXT(MONTH(AL3),"00")&"_"&TEXT(DAY(AL3),"00") -> 2026_04_03 | AQ3: {=IFERROR( _xlfn.DROP( "MD " &_xlfn._TRO_TRAILING( AP:AP), ROW(AQ3)-1), "<<<<<<<<<<<<<<<")} -> <<<<<<<<<<<<<<<
A4: 46294 | D4: FY27 | E4: =TEXT( F4, "ddd") -> Tue | F4: =F3+1 -> 46112 | G4: =G3+1 -> 46147 | H4: =H3+1 -> 46175 | I4: =I3+1 -> 46203 | J4: =J3+1 -> 46238 | K4: =K3+1 -> 46266 | L4: =L3+1 -> 46294 | M4: =M3+1 -> 46329 | ... Q4: =Q3+1 -> 46448 | U4: =YEAR(F4)&"_"&TEXT(MONTH(F4),"00")&"_"&TEXT(DAY(F4),"00") -> 2026_03_31 | V4: =YEAR(G4)&"_"&TEXT(MONTH(G4),"00")&"_"&TEXT(DAY(G4),"00") -> 2026_05_05 | W4: =YEAR(H4)&"_"&TEXT(MONTH(H4),"00")&"_"&TEXT(DAY(H4),"00") -> 2026_06_02 | X4: =YEAR(I4)&"_"&TEXT(MONTH(I4),"00")&"_"&TEXT(DAY(I4),"00") -> 2026_06_30 | Y4: =YEAR(J4)&"_"&TEXT(MONTH(J4),"00")&"_"&TEXT(DAY(J4),"00") -> 2026_08_04 | Z4: =YEAR(K4)&"_"&TEXT(MONTH(K4),"00")&"_"&TEXT(DAY(K4),"00") -> 2026_09_01 | AA4: =YEAR(L4)&"_"&TEXT(MONTH(L4),"00")&"_"&TEXT(DAY(L4),"00") -> 2026_09_29 | AB4: =YEAR(M4)&"_"&TEXT(MONTH(M4),"00")&"_"&TEXT(DAY(M4),"00") -> 2026_11_03 | ... AF4: =YEAR(Q4)&"_"&TEXT(MONTH(Q4),"00")&"_"&TEXT(DAY(Q4),"00") -> 2027_03_02 | AJ4: FY27 | AK4: Mon | AL4: 46118 | AM4: =YEAR(AL4)&"_"&TEXT(MONTH(AL4),"00")&"_"&TEXT(DAY(AL4),"00") -> 2026_04_06
A5: 46295 | D5: FY27 | E5: =TEXT( F5, "ddd") -> Wed | F5: =F4+1 -> 46113 | G5: =G4+1 -> 46148 | H5: =H4+1 -> 46176 | I5: =I4+1 -> 46204 | J5: =J4+1 -> 46239 | K5: =K4+1 -> 46267 | L5: =L4+1 -> 46295 | M5: =M4+1 -> 46330 | ... Q5: =Q4+1 -> 46449 | U5: =YEAR(F5)&"_"&TEXT(MONTH(F5),"00")&"_"&TEXT(DAY(F5),"00") -> 2026_04_01 | V5: =YEAR(G5)&"_"&TEXT(MONTH(G5),"00")&"_"&TEXT(DAY(G5),"00") -> 2026_05_06 | W5: =YEAR(H5)&"_"&TEXT(MONTH(H5),"00")&"_"&TEXT(DAY(H5),"00") -> 2026_06_03 | X5: =YEAR(I5)&"_"&TEXT(MONTH(I5),"00")&"_"&TEXT(DAY(I5),"00") -> 2026_07_01 | Y5: =YEAR(J5)&"_"&TEXT(MONTH(J5),"00")&"_"&TEXT(DAY(J5),"00") -> 2026_08_05 | Z5: =YEAR(K5)&"_"&TEXT(MONTH(K5),"00")&"_"&TEXT(DAY(K5),"00") -> 2026_09_02 | AA5: =YEAR(L5)&"_"&TEXT(MONTH(L5),"00")&"_"&TEXT(DAY(L5),"00") -> 2026_09_30 | AB5: =YEAR(M5)&"_"&TEXT(MONTH(M5),"00")&"_"&TEXT(DAY(M5),"00") -> 2026_11_04 | ... AF5: =YEAR(Q5)&"_"&TEXT(MONTH(Q5),"00")&"_"&TEXT(DAY(Q5),"00") -> 2027_03_03 | AJ5: FY27 | AK5: Mon | AL5: 46146 | AM5: =YEAR(AL5)&"_"&TEXT(MONTH(AL5),"00")&"_"&TEXT(DAY(AL5),"00") -> 2026_05_04
A6: 46296 | D6: FY27 | E6: =TEXT( F6, "ddd") -> Thu | F6: =F5+1 -> 46114 | G6: =G5+1 -> 46149 | H6: =H5+1 -> 46177 | I6: =I5+1 -> 46205 | J6: =J5+1 -> 46240 | K6: =K5+1 -> 46268 | L6: =L5+1 -> 46296 | M6: =M5+1 -> 46331 | ... Q6: =Q5+1 -> 46450 | U6: =YEAR(F6)&"_"&TEXT(MONTH(F6),"00")&"_"&TEXT(DAY(F6),"00") -> 2026_04_02 | V6: =YEAR(G6)&"_"&TEXT(MONTH(G6),"00")&"_"&TEXT(DAY(G6),"00") -> 2026_05_07 | W6: =YEAR(H6)&"_"&TEXT(MONTH(H6),"00")&"_"&TEXT(DAY(H6),"00") -> 2026_06_04 | X6: =YEAR(I6)&"_"&TEXT(MONTH(I6),"00")&"_"&TEXT(DAY(I6),"00") -> 2026_07_02 | Y6: =YEAR(J6)&"_"&TEXT(MONTH(J6),"00")&"_"&TEXT(DAY(J6),"00") -> 2026_08_06 | Z6: =YEAR(K6)&"_"&TEXT(MONTH(K6),"00")&"_"&TEXT(DAY(K6),"00") -> 2026_09_03 | AA6: =YEAR(L6)&"_"&TEXT(MONTH(L6),"00")&"_"&TEXT(DAY(L6),"00") -> 2026_10_01 | AB6: =YEAR(M6)&"_"&TEXT(MONTH(M6),"00")&"_"&TEXT(DAY(M6),"00") -> 2026_11_05 | ... AF6: =YEAR(Q6)&"_"&TEXT(MONTH(Q6),"00")&"_"&TEXT(DAY(Q6),"00") -> 2027_03_04 | AJ6: FY27 | AK6: Mon | AL6: 46167 | AM6: =YEAR(AL6)&"_"&TEXT(MONTH(AL6),"00")&"_"&TEXT(DAY(AL6),"00") -> 2026_05_25
A7: 46297 | D7: FY27 | E7: =TEXT( F7, "ddd") -> Fri | F7: =F6+1 -> 46115 | G7: =G6+1 -> 46150 | H7: =H6+1 -> 46178 | I7: =I6+1 -> 46206 | J7: =J6+1 -> 46241 | K7: =K6+1 -> 46269 | L7: =L6+1 -> 46297 | M7: =M6+1 -> 46332 | ... Q7: =Q6+1 -> 46451 | U7: =YEAR(F7)&"_"&TEXT(MONTH(F7),"00")&"_"&TEXT(DAY(F7),"00") -> 2026_04_03 | V7: =YEAR(G7)&"_"&TEXT(MONTH(G7),"00")&"_"&TEXT(DAY(G7),"00") -> 2026_05_08 | W7: =YEAR(H7)&"_"&TEXT(MONTH(H7),"00")&"_"&TEXT(DAY(H7),"00") -> 2026_06_05 | X7: =YEAR(I7)&"_"&TEXT(MONTH(I7),"00")&"_"&TEXT(DAY(I7),"00") -> 2026_07_03 | Y7: =YEAR(J7)&"_"&TEXT(MONTH(J7),"00")&"_"&TEXT(DAY(J7),"00") -> 2026_08_07 | Z7: =YEAR(K7)&"_"&TEXT(MONTH(K7),"00")&"_"&TEXT(DAY(K7),"00") -> 2026_09_04 | AA7: =YEAR(L7)&"_"&TEXT(MONTH(L7),"00")&"_"&TEXT(DAY(L7),"00") -> 2026_10_02 | AB7: =YEAR(M7)&"_"&TEXT(MONTH(M7),"00")&"_"&TEXT(DAY(M7),"00") -> 2026_11_06 | ... AF7: =YEAR(Q7)&"_"&TEXT(MONTH(Q7),"00")&"_"&TEXT(DAY(Q7),"00") -> 2027_03_05 | AJ7: FY27 | AK7: Mon | AL7: 46265 | AM7: =YEAR(AL7)&"_"&TEXT(MONTH(AL7),"00")&"_"&TEXT(DAY(AL7),"00") -> 2026_08_31
A8: 46300 | D8: FY27 | E8: =TEXT( F8, "ddd") -> Mon | F8: =F7+3 -> 46118 | G8: =G7+3 -> 46153 | H8: =H7+3 -> 46181 | I8: =I7+3 -> 46209 | J8: =J7+3 -> 46244 | K8: =K7+3 -> 46272 | L8: =L7+3 -> 46300 | M8: =M7+3 -> 46335 | ... Q8: =Q7+3 -> 46454 | U8: =YEAR(F8)&"_"&TEXT(MONTH(F8),"00")&"_"&TEXT(DAY(F8),"00") -> 2026_04_06 | V8: =YEAR(G8)&"_"&TEXT(MONTH(G8),"00")&"_"&TEXT(DAY(G8),"00") -> 2026_05_11 | W8: =YEAR(H8)&"_"&TEXT(MONTH(H8),"00")&"_"&TEXT(DAY(H8),"00") -> 2026_06_08 | X8: =YEAR(I8)&"_"&TEXT(MONTH(I8),"00")&"_"&TEXT(DAY(I8),"00") -> 2026_07_06 | Y8: =YEAR(J8)&"_"&TEXT(MONTH(J8),"00")&"_"&TEXT(DAY(J8),"00") -> 2026_08_10 | Z8: =YEAR(K8)&"_"&TEXT(MONTH(K8),"00")&"_"&TEXT(DAY(K8),"00") -> 2026_09_07 | AA8: =YEAR(L8)&"_"&TEXT(MONTH(L8),"00")&"_"&TEXT(DAY(L8),"00") -> 2026_10_05 | AB8: =YEAR(M8)&"_"&TEXT(MONTH(M8),"00")&"_"&TEXT(DAY(M8),"00") -> 2026_11_09 | ... AF8: =YEAR(Q8)&"_"&TEXT(MONTH(Q8),"00")&"_"&TEXT(DAY(Q8),"00") -> 2027_03_08 | AJ8: FY27 | AK8: Fri | AL8: 46381 | AM8: =YEAR(AL8)&"_"&TEXT(MONTH(AL8),"00")&"_"&TEXT(DAY(AL8),"00") -> 2026_12_25
A9: 46301 | D9: FY27 | E9: =TEXT( F9, "ddd") -> Tue | F9: =F8+1 -> 46119 | G9: =G8+1 -> 46154 | H9: =H8+1 -> 46182 | I9: =I8+1 -> 46210 | J9: =J8+1 -> 46245 | K9: =K8+1 -> 46273 | L9: =L8+1 -> 46301 | M9: =M8+1 -> 46336 | ... Q9: =Q8+1 -> 46455 | U9: =YEAR(F9)&"_"&TEXT(MONTH(F9),"00")&"_"&TEXT(DAY(F9),"00") -> 2026_04_07 | V9: =YEAR(G9)&"_"&TEXT(MONTH(G9),"00")&"_"&TEXT(DAY(G9),"00") -> 2026_05_12 | W9: =YEAR(H9)&"_"&TEXT(MONTH(H9),"00")&"_"&TEXT(DAY(H9),"00") -> 2026_06_09 | X9: =YEAR(I9)&"_"&TEXT(MONTH(I9),"00")&"_"&TEXT(DAY(I9),"00") -> 2026_07_07 | Y9: =YEAR(J9)&"_"&TEXT(MONTH(J9),"00")&"_"&TEXT(DAY(J9),"00") -> 2026_08_11 | Z9: =YEAR(K9)&"_"&TEXT(MONTH(K9),"00")&"_"&TEXT(DAY(K9),"00") -> 2026_09_08 | AA9: =YEAR(L9)&"_"&TEXT(MONTH(L9),"00")&"_"&TEXT(DAY(L9),"00") -> 2026_10_06 | AB9: =YEAR(M9)&"_"&TEXT(MONTH(M9),"00")&"_"&TEXT(DAY(M9),"00") -> 2026_11_10 | ... AF9: =YEAR(Q9)&"_"&TEXT(MONTH(Q9),"00")&"_"&TEXT(DAY(Q9),"00") -> 2027_03_09 | AJ9: FY27 | AK9: Mon | AL9: 46384 | AM9: =YEAR(AL9)&"_"&TEXT(MONTH(AL9),"00")&"_"&TEXT(DAY(AL9),"00") -> 2026_12_28
A10: 46302 | D10: FY27 | E10: =TEXT( F10, "ddd") -> Wed | F10: =F9+1 -> 46120 | G10: =G9+1 -> 46155 | H10: =H9+1 -> 46183 | I10: =I9+1 -> 46211 | J10: =J9+1 -> 46246 | K10: =K9+1 -> 46274 | L10: =L9+1 -> 46302 | M10: =M9+1 -> 46337 | ... Q10: =Q9+1 -> 46456 | U10: =YEAR(F10)&"_"&TEXT(MONTH(F10),"00")&"_"&TEXT(DAY(F10),"00") -> 2026_04_08 | V10: =YEAR(G10)&"_"&TEXT(MONTH(G10),"00")&"_"&TEXT(DAY(G10),"00") -> 2026_05_13 | W10: =YEAR(H10)&"_"&TEXT(MONTH(H10),"00")&"_"&TEXT(DAY(H10),"00") -> 2026_06_10 | X10: =YEAR(I10)&"_"&TEXT(MONTH(I10),"00")&"_"&TEXT(DAY(I10),"00") -> 2026_07_08 | Y10: =YEAR(J10)&"_"&TEXT(MONTH(J10),"00")&"_"&TEXT(DAY(J10),"00") -> 2026_08_12 | Z10: =YEAR(K10)&"_"&TEXT(MONTH(K10),"00")&"_"&TEXT(DAY(K10),"00") -> 2026_09_09 | AA10: =YEAR(L10)&"_"&TEXT(MONTH(L10),"00")&"_"&TEXT(DAY(L10),"00") -> 2026_10_07 | AB10: =YEAR(M10)&"_"&TEXT(MONTH(M10),"00")&"_"&TEXT(DAY(M10),"00") -> 2026_11_11 | ... AF10: =YEAR(Q10)&"_"&TEXT(MONTH(Q10),"00")&"_"&TEXT(DAY(Q10),"00") -> 2027_03_10 | AJ10: FY27 | AK10: Fri | AL10: 46388 | AM10: =YEAR(AL10)&"_"&TEXT(MONTH(AL10),"00")&"_"&TEXT(DAY(AL10),"00") -> 2027_01_01
A11: 46303 | D11: FY27 | E11: =TEXT( F11, "ddd") -> Thu | F11: =F10+1 -> 46121 | G11: =G10+1 -> 46156 | H11: =H10+1 -> 46184 | I11: =I10+1 -> 46212 | J11: =J10+1 -> 46247 | K11: =K10+1 -> 46275 | L11: =L10+1 -> 46303 | M11: =M10+1 -> 46338 | ... Q11: =Q10+1 -> 46457 | U11: =YEAR(F11)&"_"&TEXT(MONTH(F11),"00")&"_"&TEXT(DAY(F11),"00") -> 2026_04_09 | V11: =YEAR(G11)&"_"&TEXT(MONTH(G11),"00")&"_"&TEXT(DAY(G11),"00") -> 2026_05_14 | W11: =YEAR(H11)&"_"&TEXT(MONTH(H11),"00")&"_"&TEXT(DAY(H11),"00") -> 2026_06_11 | X11: =YEAR(I11)&"_"&TEXT(MONTH(I11),"00")&"_"&TEXT(DAY(I11),"00") -> 2026_07_09 | Y11: =YEAR(J11)&"_"&TEXT(MONTH(J11),"00")&"_"&TEXT(DAY(J11),"00") -> 2026_08_13 | Z11: =YEAR(K11)&"_"&TEXT(MONTH(K11),"00")&"_"&TEXT(DAY(K11),"00") -> 2026_09_10 | AA11: =YEAR(L11)&"_"&TEXT(MONTH(L11),"00")&"_"&TEXT(DAY(L11),"00") -> 2026_10_08 | AB11: =YEAR(M11)&"_"&TEXT(MONTH(M11),"00")&"_"&TEXT(DAY(M11),"00") -> 2026_11_12 | ... AF11: =YEAR(Q11)&"_"&TEXT(MONTH(Q11),"00")&"_"&TEXT(DAY(Q11),"00") -> 2027_03_11 | AJ11: FY27 | AK11: Fri | AL11: 46472 | AM11: =YEAR(AL11)&"_"&TEXT(MONTH(AL11),"00")&"_"&TEXT(DAY(AL11),"00") -> 2027_03_26
A12: 46304 | D12: FY27 | E12: =TEXT( F12, "ddd") -> Fri | F12: =F11+1 -> 46122 | G12: =G11+1 -> 46157 | H12: =H11+1 -> 46185 | I12: =I11+1 -> 46213 | J12: =J11+1 -> 46248 | K12: =K11+1 -> 46276 | L12: =L11+1 -> 46304 | M12: =M11+1 -> 46339 | ... Q12: =Q11+1 -> 46458 | U12: =YEAR(F12)&"_"&TEXT(MONTH(F12),"00")&"_"&TEXT(DAY(F12),"00") -> 2026_04_10 | V12: =YEAR(G12)&"_"&TEXT(MONTH(G12),"00")&"_"&TEXT(DAY(G12),"00") -> 2026_05_15 | W12: =YEAR(H12)&"_"&TEXT(MONTH(H12),"00")&"_"&TEXT(DAY(H12),"00") -> 2026_06_12 | X12: =YEAR(I12)&"_"&TEXT(MONTH(I12),"00")&"_"&TEXT(DAY(I12),"00") -> 2026_07_10 | Y12: =YEAR(J12)&"_"&TEXT(MONTH(J12),"00")&"_"&TEXT(DAY(J12),"00") -> 2026_08_14 | Z12: =YEAR(K12)&"_"&TEXT(MONTH(K12),"00")&"_"&TEXT(DAY(K12),"00") -> 2026_09_11 | AA12: =YEAR(L12)&"_"&TEXT(MONTH(L12),"00")&"_"&TEXT(DAY(L12),"00") -> 2026_10_09 | AB12: =YEAR(M12)&"_"&TEXT(MONTH(M12),"00")&"_"&TEXT(DAY(M12),"00") -> 2026_11_13 | ... AF12: =YEAR(Q12)&"_"&TEXT(MONTH(Q12),"00")&"_"&TEXT(DAY(Q12),"00") -> 2027_03_12
A13: 46307 | D13: FY27 | E13: =TEXT( F13, "ddd") -> Mon | F13: =F12+3 -> 46125 | G13: =G12+3 -> 46160 | H13: =H12+3 -> 46188 | I13: =I12+3 -> 46216 | J13: =J12+3 -> 46251 | K13: =K12+3 -> 46279 | L13: =L12+3 -> 46307 | M13: =M12+3 -> 46342 | ... Q13: =Q12+3 -> 46461 | U13: =YEAR(F13)&"_"&TEXT(MONTH(F13),"00")&"_"&TEXT(DAY(F13),"00") -> 2026_04_13 | V13: =YEAR(G13)&"_"&TEXT(MONTH(G13),"00")&"_"&TEXT(DAY(G13),"00") -> 2026_05_18 | W13: =YEAR(H13)&"_"&TEXT(MONTH(H13),"00")&"_"&TEXT(DAY(H13),"00") -> 2026_06_15 | X13: =YEAR(I13)&"_"&TEXT(MONTH(I13),"00")&"_"&TEXT(DAY(I13),"00") -> 2026_07_13 | Y13: =YEAR(J13)&"_"&TEXT(MONTH(J13),"00")&"_"&TEXT(DAY(J13),"00") -> 2026_08_17 | Z13: =YEAR(K13)&"_"&TEXT(MONTH(K13),"00")&"_"&TEXT(DAY(K13),"00") -> 2026_09_14 | AA13: =YEAR(L13)&"_"&TEXT(MONTH(L13),"00")&"_"&TEXT(DAY(L13),"00") -> 2026_10_12 | AB13: =YEAR(M13)&"_"&TEXT(MONTH(M13),"00")&"_"&TEXT(DAY(M13),"00") -> 2026_11_16 | ... AF13: =YEAR(Q13)&"_"&TEXT(MONTH(Q13),"00")&"_"&TEXT(DAY(Q13),"00") -> 2027_03_15 | AJ13: FY28 | AK13: Mon | AL13: 46475 | AM13: =YEAR(AL13)&"_"&TEXT(MONTH(AL13),"00")&"_"&TEXT(DAY(AL13),"00") -> 2027_03_29
A14: 46308 | D14: FY27 | E14: =TEXT( F14, "ddd") -> Tue | F14: =F13+1 -> 46126 | G14: =G13+1 -> 46161 | H14: =H13+1 -> 46189 | I14: =I13+1 -> 46217 | J14: =J13+1 -> 46252 | K14: =K13+1 -> 46280 | L14: =L13+1 -> 46308 | M14: =M13+1 -> 46343 | ... Q14: =Q13+1 -> 46462 | U14: =YEAR(F14)&"_"&TEXT(MONTH(F14),"00")&"_"&TEXT(DAY(F14),"00") -> 2026_04_14 | V14: =YEAR(G14)&"_"&TEXT(MONTH(G14),"00")&"_"&TEXT(DAY(G14),"00") -> 2026_05_19 | W14: =YEAR(H14)&"_"&TEXT(MONTH(H14),"00")&"_"&TEXT(DAY(H14),"00") -> 2026_06_16 | X14: =YEAR(I14)&"_"&TEXT(MONTH(I14),"00")&"_"&TEXT(DAY(I14),"00") -> 2026_07_14 | Y14: =YEAR(J14)&"_"&TEXT(MONTH(J14),"00")&"_"&TEXT(DAY(J14),"00") -> 2026_08_18 | Z14: =YEAR(K14)&"_"&TEXT(MONTH(K14),"00")&"_"&TEXT(DAY(K14),"00") -> 2026_09_15 | AA14: =YEAR(L14)&"_"&TEXT(MONTH(L14),"00")&"_"&TEXT(DAY(L14),"00") -> 2026_10_13 | AB14: =YEAR(M14)&"_"&TEXT(MONTH(M14),"00")&"_"&TEXT(DAY(M14),"00") -> 2026_11_17 | ... AF14: =YEAR(Q14)&"_"&TEXT(MONTH(Q14),"00")&"_"&TEXT(DAY(Q14),"00") -> 2027_03_16 | AJ14: FY28 | AK14: Mon | AL14: 46510 | AM14: =YEAR(AL14)&"_"&TEXT(MONTH(AL14),"00")&"_"&TEXT(DAY(AL14),"00") -> 2027_05_03
A15: 46309 | D15: FY27 | E15: =TEXT( F15, "ddd") -> Wed | F15: =F14+1 -> 46127 | G15: =G14+1 -> 46162 | H15: =H14+1 -> 46190 | I15: =I14+1 -> 46218 | J15: =J14+1 -> 46253 | K15: =K14+1 -> 46281 | L15: =L14+1 -> 46309 | M15: =M14+1 -> 46344 | ... Q15: =Q14+1 -> 46463 | U15: =YEAR(F15)&"_"&TEXT(MONTH(F15),"00")&"_"&TEXT(DAY(F15),"00") -> 2026_04_15 | V15: =YEAR(G15)&"_"&TEXT(MONTH(G15),"00")&"_"&TEXT(DAY(G15),"00") -> 2026_05_20 | W15: =YEAR(H15)&"_"&TEXT(MONTH(H15),"00")&"_"&TEXT(DAY(H15),"00") -> 2026_06_17 | X15: =YEAR(I15)&"_"&TEXT(MONTH(I15),"00")&"_"&TEXT(DAY(I15),"00") -> 2026_07_15 | Y15: =YEAR(J15)&"_"&TEXT(MONTH(J15),"00")&"_"&TEXT(DAY(J15),"00") -> 2026_08_19 | Z15: =YEAR(K15)&"_"&TEXT(MONTH(K15),"00")&"_"&TEXT(DAY(K15),"00") -> 2026_09_16 | AA15: =YEAR(L15)&"_"&TEXT(MONTH(L15),"00")&"_"&TEXT(DAY(L15),"00") -> 2026_10_14 | AB15: =YEAR(M15)&"_"&TEXT(MONTH(M15),"00")&"_"&TEXT(DAY(M15),"00") -> 2026_11_18 | ... AF15: =YEAR(Q15)&"_"&TEXT(MONTH(Q15),"00")&"_"&TEXT(DAY(Q15),"00") -> 2027_03_17 | AJ15: FY28 | AK15: Mon | AL15: 46538 | AM15: =YEAR(AL15)&"_"&TEXT(MONTH(AL15),"00")&"_"&TEXT(DAY(AL15),"00") -> 2027_05_31
A16: 46310 | D16: FY27 | E16: =TEXT( F16, "ddd") -> Thu | F16: =F15+1 -> 46128 | G16: =G15+1 -> 46163 | H16: =H15+1 -> 46191 | I16: =I15+1 -> 46219 | J16: =J15+1 -> 46254 | K16: =K15+1 -> 46282 | L16: =L15+1 -> 46310 | M16: =M15+1 -> 46345 | ... Q16: =Q15+1 -> 46464 | U16: =YEAR(F16)&"_"&TEXT(MONTH(F16),"00")&"_"&TEXT(DAY(F16),"00") -> 2026_04_16 | V16: =YEAR(G16)&"_"&TEXT(MONTH(G16),"00")&"_"&TEXT(DAY(G16),"00") -> 2026_05_21 | W16: =YEAR(H16)&"_"&TEXT(MONTH(H16),"00")&"_"&TEXT(DAY(H16),"00") -> 2026_06_18 | X16: =YEAR(I16)&"_"&TEXT(MONTH(I16),"00")&"_"&TEXT(DAY(I16),"00") -> 2026_07_16 | Y16: =YEAR(J16)&"_"&TEXT(MONTH(J16),"00")&"_"&TEXT(DAY(J16),"00") -> 2026_08_20 | Z16: =YEAR(K16)&"_"&TEXT(MONTH(K16),"00")&"_"&TEXT(DAY(K16),"00") -> 2026_09_17 | AA16: =YEAR(L16)&"_"&TEXT(MONTH(L16),"00")&"_"&TEXT(DAY(L16),"00") -> 2026_10_15 | AB16: =YEAR(M16)&"_"&TEXT(MONTH(M16),"00")&"_"&TEXT(DAY(M16),"00") -> 2026_11_19 | ... AF16: =YEAR(Q16)&"_"&TEXT(MONTH(Q16),"00")&"_"&TEXT(DAY(Q16),"00") -> 2027_03_18 | AJ16: FY28 | AK16: Mon | AL16: 46629 | AM16: =YEAR(AL16)&"_"&TEXT(MONTH(AL16),"00")&"_"&TEXT(DAY(AL16),"00") -> 2027_08_30
A17: 46311 | D17: FY27 | E17: =TEXT( F17, "ddd") -> Fri | F17: =F16+1 -> 46129 | G17: =G16+1 -> 46164 | H17: =H16+1 -> 46192 | I17: =I16+1 -> 46220 | J17: =J16+1 -> 46255 | K17: =K16+1 -> 46283 | L17: =L16+1 -> 46311 | M17: =M16+1 -> 46346 | ... Q17: =Q16+1 -> 46465 | U17: =YEAR(F17)&"_"&TEXT(MONTH(F17),"00")&"_"&TEXT(DAY(F17),"00") -> 2026_04_17 | V17: =YEAR(G17)&"_"&TEXT(MONTH(G17),"00")&"_"&TEXT(DAY(G17),"00") -> 2026_05_22 | W17: =YEAR(H17)&"_"&TEXT(MONTH(H17),"00")&"_"&TEXT(DAY(H17),"00") -> 2026_06_19 | X17: =YEAR(I17)&"_"&TEXT(MONTH(I17),"00")&"_"&TEXT(DAY(I17),"00") -> 2026_07_17 | Y17: =YEAR(J17)&"_"&TEXT(MONTH(J17),"00")&"_"&TEXT(DAY(J17),"00") -> 2026_08_21 | Z17: =YEAR(K17)&"_"&TEXT(MONTH(K17),"00")&"_"&TEXT(DAY(K17),"00") -> 2026_09_18 | AA17: =YEAR(L17)&"_"&TEXT(MONTH(L17),"00")&"_"&TEXT(DAY(L17),"00") -> 2026_10_16 | AB17: =YEAR(M17)&"_"&TEXT(MONTH(M17),"00")&"_"&TEXT(DAY(M17),"00") -> 2026_11_20 | ... AF17: =YEAR(Q17)&"_"&TEXT(MONTH(Q17),"00")&"_"&TEXT(DAY(Q17),"00") -> 2027_03_19 | AJ17: FY28 | AK17: Mon | AL17: 46748 | AM17: =YEAR(AL17)&"_"&TEXT(MONTH(AL17),"00")&"_"&TEXT(DAY(AL17),"00") -> 2027_12_27
A18: 46314 | D18: FY27 | E18: =TEXT( F18, "ddd") -> Mon | F18: =F17+3 -> 46132 | G18: =G17+3 -> 46167 | H18: =H17+3 -> 46195 | I18: =I17+3 -> 46223 | J18: =J17+3 -> 46258 | K18: =K17+3 -> 46286 | L18: =L17+3 -> 46314 | M18: =M17+3 -> 46349 | ... Q18: =Q17+3 -> 46468 | U18: =YEAR(F18)&"_"&TEXT(MONTH(F18),"00")&"_"&TEXT(DAY(F18),"00") -> 2026_04_20 | V18: =YEAR(G18)&"_"&TEXT(MONTH(G18),"00")&"_"&TEXT(DAY(G18),"00") -> 2026_05_25 | W18: =YEAR(H18)&"_"&TEXT(MONTH(H18),"00")&"_"&TEXT(DAY(H18),"00") -> 2026_06_22 | X18: =YEAR(I18)&"_"&TEXT(MONTH(I18),"00")&"_"&TEXT(DAY(I18),"00") -> 2026_07_20 | Y18: =YEAR(J18)&"_"&TEXT(MONTH(J18),"00")&"_"&TEXT(DAY(J18),"00") -> 2026_08_24 | Z18: =YEAR(K18)&"_"&TEXT(MONTH(K18),"00")&"_"&TEXT(DAY(K18),"00") -> 2026_09_21 | AA18: =YEAR(L18)&"_"&TEXT(MONTH(L18),"00")&"_"&TEXT(DAY(L18),"00") -> 2026_10_19 | AB18: =YEAR(M18)&"_"&TEXT(MONTH(M18),"00")&"_"&TEXT(DAY(M18),"00") -> 2026_11_23 | ... AF18: =YEAR(Q18)&"_"&TEXT(MONTH(Q18),"00")&"_"&TEXT(DAY(Q18),"00") -> 2027_03_22 | AJ18: FY28 | AK18: Tue | AL18: 46749 | AM18: =YEAR(AL18)&"_"&TEXT(MONTH(AL18),"00")&"_"&TEXT(DAY(AL18),"00") -> 2027_12_28
A19: 46315 | D19: FY27 | E19: =TEXT( F19, "ddd") -> Tue | F19: =F18+1 -> 46133 | G19: =G18+1 -> 46168 | H19: =H18+1 -> 46196 | I19: =I18+1 -> 46224 | J19: =J18+1 -> 46259 | K19: =K18+1 -> 46287 | L19: =L18+1 -> 46315 | M19: =M18+1 -> 46350 | ... Q19: =Q18+1 -> 46469 | U19: =YEAR(F19)&"_"&TEXT(MONTH(F19),"00")&"_"&TEXT(DAY(F19),"00") -> 2026_04_21 | V19: =YEAR(G19)&"_"&TEXT(MONTH(G19),"00")&"_"&TEXT(DAY(G19),"00") -> 2026_05_26 | W19: =YEAR(H19)&"_"&TEXT(MONTH(H19),"00")&"_"&TEXT(DAY(H19),"00") -> 2026_06_23 | X19: =YEAR(I19)&"_"&TEXT(MONTH(I19),"00")&"_"&TEXT(DAY(I19),"00") -> 2026_07_21 | Y19: =YEAR(J19)&"_"&TEXT(MONTH(J19),"00")&"_"&TEXT(DAY(J19),"00") -> 2026_08_25 | Z19: =YEAR(K19)&"_"&TEXT(MONTH(K19),"00")&"_"&TEXT(DAY(K19),"00") -> 2026_09_22 | AA19: =YEAR(L19)&"_"&TEXT(MONTH(L19),"00")&"_"&TEXT(DAY(L19),"00") -> 2026_10_20 | AB19: =YEAR(M19)&"_"&TEXT(MONTH(M19),"00")&"_"&TEXT(DAY(M19),"00") -> 2026_11_24 | ... AF19: =YEAR(Q19)&"_"&TEXT(MONTH(Q19),"00")&"_"&TEXT(DAY(Q19),"00") -> 2027_03_23 | AJ19: FY28 | AK19: Mon | AL19: 46755 | AM19: =YEAR(AL19)&"_"&TEXT(MONTH(AL19),"00")&"_"&TEXT(DAY(AL19),"00") -> 2028_01_03
A20: 46316 | D20: FY27 | E20: =TEXT( F20, "ddd") -> Wed | F20: =F19+1 -> 46134 | G20: =G19+1 -> 46169 | H20: =H19+1 -> 46197 | I20: =I19+1 -> 46225 | J20: =J19+1 -> 46260 | K20: =K19+1 -> 46288 | L20: =L19+1 -> 46316 | M20: =M19+1 -> 46351 | ... Q20: =Q19+1 -> 46470 | U20: =YEAR(F20)&"_"&TEXT(MONTH(F20),"00")&"_"&TEXT(DAY(F20),"00") -> 2026_04_22 | V20: =YEAR(G20)&"_"&TEXT(MONTH(G20),"00")&"_"&TEXT(DAY(G20),"00") -> 2026_05_27 | W20: =YEAR(H20)&"_"&TEXT(MONTH(H20),"00")&"_"&TEXT(DAY(H20),"00") -> 2026_06_24 | X20: =YEAR(I20)&"_"&TEXT(MONTH(I20),"00")&"_"&TEXT(DAY(I20),"00") -> 2026_07_22 | Y20: =YEAR(J20)&"_"&TEXT(MONTH(J20),"00")&"_"&TEXT(DAY(J20),"00") -> 2026_08_26 | Z20: =YEAR(K20)&"_"&TEXT(MONTH(K20),"00")&"_"&TEXT(DAY(K20),"00") -> 2026_09_23 | AA20: =YEAR(L20)&"_"&TEXT(MONTH(L20),"00")&"_"&TEXT(DAY(L20),"00") -> 2026_10_21 | AB20: =YEAR(M20)&"_"&TEXT(MONTH(M20),"00")&"_"&TEXT(DAY(M20),"00") -> 2026_11_25 | ... AF20: =YEAR(Q20)&"_"&TEXT(MONTH(Q20),"00")&"_"&TEXT(DAY(Q20),"00") -> 2027_03_24
A21: 46317 | D21: FY27 | E21: =TEXT( F21, "ddd") -> Thu | F21: =F20+1 -> 46135 | G21: =G20+1 -> 46170 | H21: =H20+1 -> 46198 | I21: =I20+1 -> 46226 | J21: =J20+1 -> 46261 | K21: =K20+1 -> 46289 | L21: =L20+1 -> 46317 | M21: =M20+1 -> 46352 | ... Q21: =Q20+1 -> 46471 | U21: =YEAR(F21)&"_"&TEXT(MONTH(F21),"00")&"_"&TEXT(DAY(F21),"00") -> 2026_04_23 | V21: =YEAR(G21)&"_"&TEXT(MONTH(G21),"00")&"_"&TEXT(DAY(G21),"00") -> 2026_05_28 | W21: =YEAR(H21)&"_"&TEXT(MONTH(H21),"00")&"_"&TEXT(DAY(H21),"00") -> 2026_06_25 | X21: =YEAR(I21)&"_"&TEXT(MONTH(I21),"00")&"_"&TEXT(DAY(I21),"00") -> 2026_07_23 | Y21: =YEAR(J21)&"_"&TEXT(MONTH(J21),"00")&"_"&TEXT(DAY(J21),"00") -> 2026_08_27 | Z21: =YEAR(K21)&"_"&TEXT(MONTH(K21),"00")&"_"&TEXT(DAY(K21),"00") -> 2026_09_24 | AA21: =YEAR(L21)&"_"&TEXT(MONTH(L21),"00")&"_"&TEXT(DAY(L21),"00") -> 2026_10_22 | AB21: =YEAR(M21)&"_"&TEXT(MONTH(M21),"00")&"_"&TEXT(DAY(M21),"00") -> 2026_11_26 | ... AF21: =YEAR(Q21)&"_"&TEXT(MONTH(Q21),"00")&"_"&TEXT(DAY(Q21),"00") -> 2027_03_25 | AJ21: FY29 | AK21: Fri | AL21: 46857 | AM21: =YEAR(AL21)&"_"&TEXT(MONTH(AL21),"00")&"_"&TEXT(DAY(AL21),"00") -> 2028_04_14
A22: 46318 | D22: FY27 | E22: =TEXT( F22, "ddd") -> Fri | F22: =F21+1 -> 46136 | G22: =G21+1 -> 46171 | H22: =H21+1 -> 46199 | I22: =I21+1 -> 46227 | J22: =J21+1 -> 46262 | K22: =K21+1 -> 46290 | L22: =L21+1 -> 46318 | M22: =M21+1 -> 46353 | ... Q22: =Q21+1 -> 46472 | U22: =YEAR(F22)&"_"&TEXT(MONTH(F22),"00")&"_"&TEXT(DAY(F22),"00") -> 2026_04_24 | V22: =YEAR(G22)&"_"&TEXT(MONTH(G22),"00")&"_"&TEXT(DAY(G22),"00") -> 2026_05_29 | W22: =YEAR(H22)&"_"&TEXT(MONTH(H22),"00")&"_"&TEXT(DAY(H22),"00") -> 2026_06_26 | X22: =YEAR(I22)&"_"&TEXT(MONTH(I22),"00")&"_"&TEXT(DAY(I22),"00") -> 2026_07_24 | Y22: =YEAR(J22)&"_"&TEXT(MONTH(J22),"00")&"_"&TEXT(DAY(J22),"00") -> 2026_08_28 | Z22: =YEAR(K22)&"_"&TEXT(MONTH(K22),"00")&"_"&TEXT(DAY(K22),"00") -> 2026_09_25 | AA22: =YEAR(L22)&"_"&TEXT(MONTH(L22),"00")&"_"&TEXT(DAY(L22),"00") -> 2026_10_23 | AB22: =YEAR(M22)&"_"&TEXT(MONTH(M22),"00")&"_"&TEXT(DAY(M22),"00") -> 2026_11_27 | ... AF22: =YEAR(Q22)&"_"&TEXT(MONTH(Q22),"00")&"_"&TEXT(DAY(Q22),"00") -> 2027_03_26 | AJ22: FY29 | AK22: Mon | AL22: 46860 | AM22: =YEAR(AL22)&"_"&TEXT(MONTH(AL22),"00")&"_"&TEXT(DAY(AL22),"00") -> 2028_04_17
A23: 46321 | D23: FY27 | E23: =TEXT( F23, "ddd") -> Mon | F23: =F22+3 -> 46139 | I23: =I22+3 -> 46230 | L23: =L22+3 -> 46321 | O23: =O22+3 -> 46412 | U23: =YEAR(F23)&"_"&TEXT(MONTH(F23),"00")&"_"&TEXT(DAY(F23),"00") -> 2026_04_27 | X23: =YEAR(I23)&"_"&TEXT(MONTH(I23),"00")&"_"&TEXT(DAY(I23),"00") -> 2026_07_27 | AA23: =YEAR(L23)&"_"&TEXT(MONTH(L23),"00")&"_"&TEXT(DAY(L23),"00") -> 2026_10_26 | AD23: =YEAR(O23)&"_"&TEXT(MONTH(O23),"00")&"_"&TEXT(DAY(O23),"00") -> 2027_01_25 | AJ23: FY29 | AK23: Mon | AL23: 46874 | AM23: =YEAR(AL23)&"_"&TEXT(MONTH(AL23),"00")&"_"&TEXT(DAY(AL23),"00") -> 2028_05_01
A24: 46322 | D24: FY27 | E24: =TEXT( F24, "ddd") -> Tue | F24: =F23+1 -> 46140 | I24: =I23+1 -> 46231 | L24: =L23+1 -> 46322 | O24: =O23+1 -> 46413 | U24: =YEAR(F24)&"_"&TEXT(MONTH(F24),"00")&"_"&TEXT(DAY(F24),"00") -> 2026_04_28 | X24: =YEAR(I24)&"_"&TEXT(MONTH(I24),"00")&"_"&TEXT(DAY(I24),"00") -> 2026_07_28 | AA24: =YEAR(L24)&"_"&TEXT(MONTH(L24),"00")&"_"&TEXT(DAY(L24),"00") -> 2026_10_27 | AD24: =YEAR(O24)&"_"&TEXT(MONTH(O24),"00")&"_"&TEXT(DAY(O24),"00") -> 2027_01_26 | AJ24: FY29 | AK24: Mon | AL24: 46902 | AM24: =YEAR(AL24)&"_"&TEXT(MONTH(AL24),"00")&"_"&TEXT(DAY(AL24),"00") -> 2028_05_29
A25: 46323 | D25: FY27 | E25: =TEXT( F25, "ddd") -> Wed | F25: =F24+1 -> 46141 | I25: =I24+1 -> 46232 | L25: =L24+1 -> 46323 | O25: =O24+1 -> 46414 | U25: =YEAR(F25)&"_"&TEXT(MONTH(F25),"00")&"_"&TEXT(DAY(F25),"00") -> 2026_04_29 | X25: =YEAR(I25)&"_"&TEXT(MONTH(I25),"00")&"_"&TEXT(DAY(I25),"00") -> 2026_07_29 | AA25: =YEAR(L25)&"_"&TEXT(MONTH(L25),"00")&"_"&TEXT(DAY(L25),"00") -> 2026_10_28 | AD25: =YEAR(O25)&"_"&TEXT(MONTH(O25),"00")&"_"&TEXT(DAY(O25),"00") -> 2027_01_27 | AJ25: FY29 | AK25: Mon | AL25: 46993 | AM25: =YEAR(AL25)&"_"&TEXT(MONTH(AL25),"00")&"_"&TEXT(DAY(AL25),"00") -> 2028_08_28
A26: 46324 | D26: FY27 | E26: =TEXT( F26, "ddd") -> Thu | F26: =F25+1 -> 46142 | I26: =I25+1 -> 46233 | L26: =L25+1 -> 46324 | O26: =O25+1 -> 46415 | U26: =YEAR(F26)&"_"&TEXT(MONTH(F26),"00")&"_"&TEXT(DAY(F26),"00") -> 2026_04_30 | X26: =YEAR(I26)&"_"&TEXT(MONTH(I26),"00")&"_"&TEXT(DAY(I26),"00") -> 2026_07_30 | AA26: =YEAR(L26)&"_"&TEXT(MONTH(L26),"00")&"_"&TEXT(DAY(L26),"00") -> 2026_10_29 | AD26: =YEAR(O26)&"_"&TEXT(MONTH(O26),"00")&"_"&TEXT(DAY(O26),"00") -> 2027_01_28 | AJ26: FY29 | AK26: Mon | AL26: 47112 | AM26: =YEAR(AL26)&"_"&TEXT(MONTH(AL26),"00")&"_"&TEXT(DAY(AL26),"00") -> 2028_12_25
A27: 46325 | D27: FY27 | E27: =TEXT( F27, "ddd") -> Fri | F27: =F26+1 -> 46143 | I27: =I26+1 -> 46234 | L27: =L26+1 -> 46325 | O27: =O26+1 -> 46416 | U27: =YEAR(F27)&"_"&TEXT(MONTH(F27),"00")&"_"&TEXT(DAY(F27),"00") -> 2026_05_01 | X27: =YEAR(I27)&"_"&TEXT(MONTH(I27),"00")&"_"&TEXT(DAY(I27),"00") -> 2026_07_31 | AA27: =YEAR(L27)&"_"&TEXT(MONTH(L27),"00")&"_"&TEXT(DAY(L27),"00") -> 2026_10_30 | AD27: =YEAR(O27)&"_"&TEXT(MONTH(O27),"00")&"_"&TEXT(DAY(O27),"00") -> 2027_01_29 | AJ27: FY29 | AK27: Tue | AL27: 47113 | AM27: =YEAR(AL27)&"_"&TEXT(MONTH(AL27),"00")&"_"&TEXT(DAY(AL27),"00") -> 2028_12_26
AJ28: FY29 | AK28: Mon | AL28: 47119 | AM28: =YEAR(AL28)&"_"&TEXT(MONTH(AL28),"00")&"_"&TEXT(DAY(AL28),"00") -> 2029_01_01
AJ29: FY29 | AK29: Fri | AL29: 47207 | AM29: =YEAR(AL29)&"_"&TEXT(MONTH(AL29),"00")&"_"&TEXT(DAY(AL29),"00") -> 2029_03_30
A30: Column1 | C30: FY28 | D30: FY28 | E30: =TEXT( F30, "ddd") -> Mon | F30: =Q22+3 -> 46475 | G30: =F54+3 -> 46510 | H30: =G49+3 -> 46538 | I30: =H49+3 -> 46566 | J30: =I54+3 -> 46601 | K30: =J49+3 -> 46629 | L30: =K49+3 -> 46657 | M30: =L54+3 -> 46692 | N30: =M49+3 -> 46720 | O30: =N49+3 -> 46748 | P30: =O54+3 -> 46783 | Q30: =P49+3 -> 46811 | U30: =YEAR(F30)&"_"&TEXT(MONTH(F30),"00")&"_"&TEXT(DAY(F30),"00") -> 2027_03_29 | V30: =YEAR(G30)&"_"&TEXT(MONTH(G30),"00")&"_"&TEXT(DAY(G30),"00") -> 2027_05_03 | W30: =YEAR(H30)&"_"&TEXT(MONTH(H30),"00")&"_"&TEXT(DAY(H30),"00") -> 2027_05_31 | X30: =YEAR(I30)&"_"&TEXT(MONTH(I30),"00")&"_"&TEXT(DAY(I30),"00") -> 2027_06_28 | Y30: =YEAR(J30)&"_"&TEXT(MONTH(J30),"00")&"_"&TEXT(DAY(J30),"00") -> 2027_08_02 | Z30: =YEAR(K30)&"_"&TEXT(MONTH(K30),"00")&"_"&TEXT(DAY(K30),"00") -> 2027_08_30 | AA30: =YEAR(L30)&"_"&TEXT(MONTH(L30),"00")&"_"&TEXT(DAY(L30),"00") -> 2027_09_27 | AB30: =YEAR(M30)&"_"&TEXT(MONTH(M30),"00")&"_"&TEXT(DAY(M30),"00") -> 2027_11_01 | ... AF30: =YEAR(Q30)&"_"&TEXT(MONTH(Q30),"00")&"_"&TEXT(DAY(Q30),"00") -> 2028_02_28
A31: ='Date picker'!C8 -> 46234 | D31: FY28 | E31: =TEXT( F31, "ddd") -> Tue | F31: =F30+1 -> 46476 | G31: =G30+1 -> 46511 | H31: =H30+1 -> 46539 | I31: =I30+1 -> 46567 | J31: =J30+1 -> 46602 | K31: =K30+1 -> 46630 | L31: =L30+1 -> 46658 | M31: =M30+1 -> 46693 | ... Q31: =Q30+1 -> 46812 | U31: =YEAR(F31)&"_"&TEXT(MONTH(F31),"00")&"_"&TEXT(DAY(F31),"00") -> 2027_03_30 | V31: =YEAR(G31)&"_"&TEXT(MONTH(G31),"00")&"_"&TEXT(DAY(G31),"00") -> 2027_05_04 | W31: =YEAR(H31)&"_"&TEXT(MONTH(H31),"00")&"_"&TEXT(DAY(H31),"00") -> 2027_06_01 | X31: =YEAR(I31)&"_"&TEXT(MONTH(I31),"00")&"_"&TEXT(DAY(I31),"00") -> 2027_06_29 | Y31: =YEAR(J31)&"_"&TEXT(MONTH(J31),"00")&"_"&TEXT(DAY(J31),"00") -> 2027_08_03 | Z31: =YEAR(K31)&"_"&TEXT(MONTH(K31),"00")&"_"&TEXT(DAY(K31),"00") -> 2027_08_31 | AA31: =YEAR(L31)&"_"&TEXT(MONTH(L31),"00")&"_"&TEXT(DAY(L31),"00") -> 2027_09_28 | AB31: =YEAR(M31)&"_"&TEXT(MONTH(M31),"00")&"_"&TEXT(DAY(M31),"00") -> 2027_11_02 | ... AF31: =YEAR(Q31)&"_"&TEXT(MONTH(Q31),"00")&"_"&TEXT(DAY(Q31),"00") -> 2028_02_29 | AJ31: FY30 | AK31: Mon | AL31: 47210 | AM31: =YEAR(AL31)&"_"&TEXT(MONTH(AL31),"00")&"_"&TEXT(DAY(AL31),"00") -> 2029_04_02
D32: FY28 | E32: =TEXT( F32, "ddd") -> Wed | F32: =F31+1 -> 46477 | G32: =G31+1 -> 46512 | H32: =H31+1 -> 46540 | I32: =I31+1 -> 46568 | J32: =J31+1 -> 46603 | K32: =K31+1 -> 46631 | L32: =L31+1 -> 46659 | M32: =M31+1 -> 46694 | ... Q32: =Q31+1 -> 46813 | U32: =YEAR(F32)&"_"&TEXT(MONTH(F32),"00")&"_"&TEXT(DAY(F32),"00") -> 2027_03_31 | V32: =YEAR(G32)&"_"&TEXT(MONTH(G32),"00")&"_"&TEXT(DAY(G32),"00") -> 2027_05_05 | W32: =YEAR(H32)&"_"&TEXT(MONTH(H32),"00")&"_"&TEXT(DAY(H32),"00") -> 2027_06_02 | X32: =YEAR(I32)&"_"&TEXT(MONTH(I32),"00")&"_"&TEXT(DAY(I32),"00") -> 2027_06_30 | Y32: =YEAR(J32)&"_"&TEXT(MONTH(J32),"00")&"_"&TEXT(DAY(J32),"00") -> 2027_08_04 | Z32: =YEAR(K32)&"_"&TEXT(MONTH(K32),"00")&"_"&TEXT(DAY(K32),"00") -> 2027_09_01 | AA32: =YEAR(L32)&"_"&TEXT(MONTH(L32),"00")&"_"&TEXT(DAY(L32),"00") -> 2027_09_29 | AB32: =YEAR(M32)&"_"&TEXT(MONTH(M32),"00")&"_"&TEXT(DAY(M32),"00") -> 2027_11_03 | ... AF32: =YEAR(Q32)&"_"&TEXT(MONTH(Q32),"00")&"_"&TEXT(DAY(Q32),"00") -> 2028_03_01 | AJ32: FY30 | AK32: Mon | AL32: 47245 | AM32: =YEAR(AL32)&"_"&TEXT(MONTH(AL32),"00")&"_"&TEXT(DAY(AL32),"00") -> 2029_05_07
D33: FY28 | E33: =TEXT( F33, "ddd") -> Thu | F33: =F32+1 -> 46478 | G33: =G32+1 -> 46513 | H33: =H32+1 -> 46541 | I33: =I32+1 -> 46569 | J33: =J32+1 -> 46604 | K33: =K32+1 -> 46632 | L33: =L32+1 -> 46660 | M33: =M32+1 -> 46695 | ... Q33: =Q32+1 -> 46814 | U33: =YEAR(F33)&"_"&TEXT(MONTH(F33),"00")&"_"&TEXT(DAY(F33),"00") -> 2027_04_01 | V33: =YEAR(G33)&"_"&TEXT(MONTH(G33),"00")&"_"&TEXT(DAY(G33),"00") -> 2027_05_06 | W33: =YEAR(H33)&"_"&TEXT(MONTH(H33),"00")&"_"&TEXT(DAY(H33),"00") -> 2027_06_03 | X33: =YEAR(I33)&"_"&TEXT(MONTH(I33),"00")&"_"&TEXT(DAY(I33),"00") -> 2027_07_01 | Y33: =YEAR(J33)&"_"&TEXT(MONTH(J33),"00")&"_"&TEXT(DAY(J33),"00") -> 2027_08_05 | Z33: =YEAR(K33)&"_"&TEXT(MONTH(K33),"00")&"_"&TEXT(DAY(K33),"00") -> 2027_09_02 | AA33: =YEAR(L33)&"_"&TEXT(MONTH(L33),"00")&"_"&TEXT(DAY(L33),"00") -> 2027_09_30 | AB33: =YEAR(M33)&"_"&TEXT(MONTH(M33),"00")&"_"&TEXT(DAY(M33),"00") -> 2027_11_04 | ... AF33: =YEAR(Q33)&"_"&TEXT(MONTH(Q33),"00")&"_"&TEXT(DAY(Q33),"00") -> 2028_03_02 | AJ33: FY30 | AK33: Mon | AL33: 47266 | AM33: =YEAR(AL33)&"_"&TEXT(MONTH(AL33),"00")&"_"&TEXT(DAY(AL33),"00") -> 2029_05_28
D34: FY28 | E34: =TEXT( F34, "ddd") -> Fri | F34: =F33+1 -> 46479 | G34: =G33+1 -> 46514 | H34: =H33+1 -> 46542 | I34: =I33+1 -> 46570 | J34: =J33+1 -> 46605 | K34: =K33+1 -> 46633 | L34: =L33+1 -> 46661 | M34: =M33+1 -> 46696 | ... Q34: =Q33+1 -> 46815 | U34: =YEAR(F34)&"_"&TEXT(MONTH(F34),"00")&"_"&TEXT(DAY(F34),"00") -> 2027_04_02 | V34: =YEAR(G34)&"_"&TEXT(MONTH(G34),"00")&"_"&TEXT(DAY(G34),"00") -> 2027_05_07 | W34: =YEAR(H34)&"_"&TEXT(MONTH(H34),"00")&"_"&TEXT(DAY(H34),"00") -> 2027_06_04 | X34: =YEAR(I34)&"_"&TEXT(MONTH(I34),"00")&"_"&TEXT(DAY(I34),"00") -> 2027_07_02 | Y34: =YEAR(J34)&"_"&TEXT(MONTH(J34),"00")&"_"&TEXT(DAY(J34),"00") -> 2027_08_06 | Z34: =YEAR(K34)&"_"&TEXT(MONTH(K34),"00")&"_"&TEXT(DAY(K34),"00") -> 2027_09_03 | AA34: =YEAR(L34)&"_"&TEXT(MONTH(L34),"00")&"_"&TEXT(DAY(L34),"00") -> 2027_10_01 | AB34: =YEAR(M34)&"_"&TEXT(MONTH(M34),"00")&"_"&TEXT(DAY(M34),"00") -> 2027_11_05 | ... AF34: =YEAR(Q34)&"_"&TEXT(MONTH(Q34),"00")&"_"&TEXT(DAY(Q34),"00") -> 2028_03_03 | AJ34: FY30 | AK34: Mon | AL34: 47357 | AM34: =YEAR(AL34)&"_"&TEXT(MONTH(AL34),"00")&"_"&TEXT(DAY(AL34),"00") -> 2029_08_27
D35: FY28 | E35: =TEXT( F35, "ddd") -> Mon | F35: =F34+3 -> 46482 | G35: =G34+3 -> 46517 | H35: =H34+3 -> 46545 | I35: =I34+3 -> 46573 | J35: =J34+3 -> 46608 | K35: =K34+3 -> 46636 | L35: =L34+3 -> 46664 | M35: =M34+3 -> 46699 | ... Q35: =Q34+3 -> 46818 | U35: =YEAR(F35)&"_"&TEXT(MONTH(F35),"00")&"_"&TEXT(DAY(F35),"00") -> 2027_04_05 | V35: =YEAR(G35)&"_"&TEXT(MONTH(G35),"00")&"_"&TEXT(DAY(G35),"00") -> 2027_05_10 | W35: =YEAR(H35)&"_"&TEXT(MONTH(H35),"00")&"_"&TEXT(DAY(H35),"00") -> 2027_06_07 | X35: =YEAR(I35)&"_"&TEXT(MONTH(I35),"00")&"_"&TEXT(DAY(I35),"00") -> 2027_07_05 | Y35: =YEAR(J35)&"_"&TEXT(MONTH(J35),"00")&"_"&TEXT(DAY(J35),"00") -> 2027_08_09 | Z35: =YEAR(K35)&"_"&TEXT(MONTH(K35),"00")&"_"&TEXT(DAY(K35),"00") -> 2027_09_06 | AA35: =YEAR(L35)&"_"&TEXT(MONTH(L35),"00")&"_"&TEXT(DAY(L35),"00") -> 2027_10_04 | AB35: =YEAR(M35)&"_"&TEXT(MONTH(M35),"00")&"_"&TEXT(DAY(M35),"00") -> 2027_11_08 | ... AF35: =YEAR(Q35)&"_"&TEXT(MONTH(Q35),"00")&"_"&TEXT(DAY(Q35),"00") -> 2028_03_06 | AJ35: FY30 | AK35: Tue | AL35: 47477 | AM35: =YEAR(AL35)&"_"&TEXT(MONTH(AL35),"00")&"_"&TEXT(DAY(AL35),"00") -> 2029_12_25
D36: FY28 | E36: =TEXT( F36, "ddd") -> Tue | F36: =F35+1 -> 46483 | G36: =G35+1 -> 46518 | H36: =H35+1 -> 46546 | I36: =I35+1 -> 46574 | J36: =J35+1 -> 46609 | K36: =K35+1 -> 46637 | L36: =L35+1 -> 46665 | M36: =M35+1 -> 46700 | ... Q36: =Q35+1 -> 46819 | U36: =YEAR(F36)&"_"&TEXT(MONTH(F36),"00")&"_"&TEXT(DAY(F36),"00") -> 2027_04_06 | V36: =YEAR(G36)&"_"&TEXT(MONTH(G36),"00")&"_"&TEXT(DAY(G36),"00") -> 2027_05_11 | W36: =YEAR(H36)&"_"&TEXT(MONTH(H36),"00")&"_"&TEXT(DAY(H36),"00") -> 2027_06_08 | X36: =YEAR(I36)&"_"&TEXT(MONTH(I36),"00")&"_"&TEXT(DAY(I36),"00") -> 2027_07_06 | Y36: =YEAR(J36)&"_"&TEXT(MONTH(J36),"00")&"_"&TEXT(DAY(J36),"00") -> 2027_08_10 | Z36: =YEAR(K36)&"_"&TEXT(MONTH(K36),"00")&"_"&TEXT(DAY(K36),"00") -> 2027_09_07 | AA36: =YEAR(L36)&"_"&TEXT(MONTH(L36),"00")&"_"&TEXT(DAY(L36),"00") -> 2027_10_05 | AB36: =YEAR(M36)&"_"&TEXT(MONTH(M36),"00")&"_"&TEXT(DAY(M36),"00") -> 2027_11_09 | ... AF36: =YEAR(Q36)&"_"&TEXT(MONTH(Q36),"00")&"_"&TEXT(DAY(Q36),"00") -> 2028_03_07 | AJ36: FY30 | AK36: Wed | AL36: 47478 | AM36: =YEAR(AL36)&"_"&TEXT(MONTH(AL36),"00")&"_"&TEXT(DAY(AL36),"00") -> 2029_12_26
D37: FY28 | E37: =TEXT( F37, "ddd") -> Wed | F37: =F36+1 -> 46484 | G37: =G36+1 -> 46519 | H37: =H36+1 -> 46547 | I37: =I36+1 -> 46575 | J37: =J36+1 -> 46610 | K37: =K36+1 -> 46638 | L37: =L36+1 -> 46666 | M37: =M36+1 -> 46701 | ... Q37: =Q36+1 -> 46820 | U37: =YEAR(F37)&"_"&TEXT(MONTH(F37),"00")&"_"&TEXT(DAY(F37),"00") -> 2027_04_07 | V37: =YEAR(G37)&"_"&TEXT(MONTH(G37),"00")&"_"&TEXT(DAY(G37),"00") -> 2027_05_12 | W37: =YEAR(H37)&"_"&TEXT(MONTH(H37),"00")&"_"&TEXT(DAY(H37),"00") -> 2027_06_09 | X37: =YEAR(I37)&"_"&TEXT(MONTH(I37),"00")&"_"&TEXT(DAY(I37),"00") -> 2027_07_07 | Y37: =YEAR(J37)&"_"&TEXT(MONTH(J37),"00")&"_"&TEXT(DAY(J37),"00") -> 2027_08_11 | Z37: =YEAR(K37)&"_"&TEXT(MONTH(K37),"00")&"_"&TEXT(DAY(K37),"00") -> 2027_09_08 | AA37: =YEAR(L37)&"_"&TEXT(MONTH(L37),"00")&"_"&TEXT(DAY(L37),"00") -> 2027_10_06 | AB37: =YEAR(M37)&"_"&TEXT(MONTH(M37),"00")&"_"&TEXT(DAY(M37),"00") -> 2027_11_10 | ... AF37: =YEAR(Q37)&"_"&TEXT(MONTH(Q37),"00")&"_"&TEXT(DAY(Q37),"00") -> 2028_03_08 | AJ37: FY30 | AK37: Tue | AL37: 47484 | AM37: =YEAR(AL37)&"_"&TEXT(MONTH(AL37),"00")&"_"&TEXT(DAY(AL37),"00") -> 2030_01_01
D38: FY28 | E38: =TEXT( F38, "ddd") -> Thu | F38: =F37+1 -> 46485 | G38: =G37+1 -> 46520 | H38: =H37+1 -> 46548 | I38: =I37+1 -> 46576 | J38: =J37+1 -> 46611 | K38: =K37+1 -> 46639 | L38: =L37+1 -> 46667 | M38: =M37+1 -> 46702 | ... Q38: =Q37+1 -> 46821 | U38: =YEAR(F38)&"_"&TEXT(MONTH(F38),"00")&"_"&TEXT(DAY(F38),"00") -> 2027_04_08 | V38: =YEAR(G38)&"_"&TEXT(MONTH(G38),"00")&"_"&TEXT(DAY(G38),"00") -> 2027_05_13 | W38: =YEAR(H38)&"_"&TEXT(MONTH(H38),"00")&"_"&TEXT(DAY(H38),"00") -> 2027_06_10 | X38: =YEAR(I38)&"_"&TEXT(MONTH(I38),"00")&"_"&TEXT(DAY(I38),"00") -> 2027_07_08 | Y38: =YEAR(J38)&"_"&TEXT(MONTH(J38),"00")&"_"&TEXT(DAY(J38),"00") -> 2027_08_12 | Z38: =YEAR(K38)&"_"&TEXT(MONTH(K38),"00")&"_"&TEXT(DAY(K38),"00") -> 2027_09_09 | AA38: =YEAR(L38)&"_"&TEXT(MONTH(L38),"00")&"_"&TEXT(DAY(L38),"00") -> 2027_10_07 | AB38: =YEAR(M38)&"_"&TEXT(MONTH(M38),"00")&"_"&TEXT(DAY(M38),"00") -> 2027_11_11 | ... AF38: =YEAR(Q38)&"_"&TEXT(MONTH(Q38),"00")&"_"&TEXT(DAY(Q38),"00") -> 2028_03_09
D39: FY28 | E39: =TEXT( F39, "ddd") -> Fri | F39: =F38+1 -> 46486 | G39: =G38+1 -> 46521 | H39: =H38+1 -> 46549 | I39: =I38+1 -> 46577 | J39: =J38+1 -> 46612 | K39: =K38+1 -> 46640 | L39: =L38+1 -> 46668 | M39: =M38+1 -> 46703 | ... Q39: =Q38+1 -> 46822 | U39: =YEAR(F39)&"_"&TEXT(MONTH(F39),"00")&"_"&TEXT(DAY(F39),"00") -> 2027_04_09 | V39: =YEAR(G39)&"_"&TEXT(MONTH(G39),"00")&"_"&TEXT(DAY(G39),"00") -> 2027_05_14 | W39: =YEAR(H39)&"_"&TEXT(MONTH(H39),"00")&"_"&TEXT(DAY(H39),"00") -> 2027_06_11 | X39: =YEAR(I39)&"_"&TEXT(MONTH(I39),"00")&"_"&TEXT(DAY(I39),"00") -> 2027_07_09 | Y39: =YEAR(J39)&"_"&TEXT(MONTH(J39),"00")&"_"&TEXT(DAY(J39),"00") -> 2027_08_13 | Z39: =YEAR(K39)&"_"&TEXT(MONTH(K39),"00")&"_"&TEXT(DAY(K39),"00") -> 2027_09_10 | AA39: =YEAR(L39)&"_"&TEXT(MONTH(L39),"00")&"_"&TEXT(DAY(L39),"00") -> 2027_10_08 | AB39: =YEAR(M39)&"_"&TEXT(MONTH(M39),"00")&"_"&TEXT(DAY(M39),"00") -> 2027_11_12 | ... AF39: =YEAR(Q39)&"_"&TEXT(MONTH(Q39),"00")&"_"&TEXT(DAY(Q39),"00") -> 2028_03_10 | AJ39: FY31 | AK39: Fri | AL39: 47592 | AM39: =YEAR(AL39)&"_"&TEXT(MONTH(AL39),"00")&"_"&TEXT(DAY(AL39),"00") -> 2030_04_19
D40: FY28 | E40: =TEXT( F40, "ddd") -> Mon | F40: =F39+3 -> 46489 | G40: =G39+3 -> 46524 | H40: =H39+3 -> 46552 | I40: =I39+3 -> 46580 | J40: =J39+3 -> 46615 | K40: =K39+3 -> 46643 | L40: =L39+3 -> 46671 | M40: =M39+3 -> 46706 | ... Q40: =Q39+3 -> 46825 | U40: =YEAR(F40)&"_"&TEXT(MONTH(F40),"00")&"_"&TEXT(DAY(F40),"00") -> 2027_04_12 | V40: =YEAR(G40)&"_"&TEXT(MONTH(G40),"00")&"_"&TEXT(DAY(G40),"00") -> 2027_05_17 | W40: =YEAR(H40)&"_"&TEXT(MONTH(H40),"00")&"_"&TEXT(DAY(H40),"00") -> 2027_06_14 | X40: =YEAR(I40)&"_"&TEXT(MONTH(I40),"00")&"_"&TEXT(DAY(I40),"00") -> 2027_07_12 | Y40: =YEAR(J40)&"_"&TEXT(MONTH(J40),"00")&"_"&TEXT(DAY(J40),"00") -> 2027_08_16 | Z40: =YEAR(K40)&"_"&TEXT(MONTH(K40),"00")&"_"&TEXT(DAY(K40),"00") -> 2027_09_13 | AA40: =YEAR(L40)&"_"&TEXT(MONTH(L40),"00")&"_"&TEXT(DAY(L40),"00") -> 2027_10_11 | AB40: =YEAR(M40)&"_"&TEXT(MONTH(M40),"00")&"_"&TEXT(DAY(M40),"00") -> 2027_11_15 | ... AF40: =YEAR(Q40)&"_"&TEXT(MONTH(Q40),"00")&"_"&TEXT(DAY(Q40),"00") -> 2028_03_13 | AJ40: FY31 | AK40: Mon | AL40: 47595 | AM40: =YEAR(AL40)&"_"&TEXT(MONTH(AL40),"00")&"_"&TEXT(DAY(AL40),"00") -> 2030_04_22
...
